<?xml version='1.0'?>
<sdf version="1.0">
<model name="jeff_electrician_modular">
  <pose>0 0 0.5 0 0 0</pose>
  <static>false</static>
    <link name="body_link">
      <inertial>
        <mass>66.0</mass>
        <inertia> <!-- inertias are tricky to compute -->
          <!-- http://gazebosim.org/tutorials?tut=inertia&cat=build_robot -->
          <ixx>-0.186819 </ixx>     
          <ixy>-0.000257 </ixy>        
          <ixz>-0.000008</ixz>         
          <iyy>0.005504</iyy>       
          <iyz>-0.003203</iyz>        
          <izz>-0.183004</izz>     
        </inertia>
      </inertial>
      <collision name="body_collision">
        <geometry>
          <mesh>
            <uri>model://jeff_electrician/jeff_body.dae</uri>
          </mesh>
        </geometry>
      </collision>
      <visual name="body_visual">
        <geometry>
          <mesh>
            <uri>model://jeff_electrician/jeff_body.dae</uri>
          </mesh>
        </geometry>
      </visual>
      <!-- <gravity>0</gravity> -->
    </link>
    <link name="left_arm_link">
      <inertial>
        <mass>7.0</mass>
        <inertia>
          <ixx>-0.186819 </ixx>     
          <ixy>-0.000257 </ixy>        
          <ixz>-0.000008</ixz>         
          <iyy>0.005504</iyy>       
          <iyz>-0.003203</iyz>        
          <izz>-0.183004</izz>    
        </inertia>
      </inertial>
      <collision name="left_arm_collision">
        <geometry>
          <mesh>
            <uri>model://jeff_electrician/jeff_left_arm.dae</uri>
          </mesh>
        </geometry>
      </collision>
      <visual name="left_arm_visual">
        <geometry>
          <mesh>
            <uri>model://jeff_electrician/jeff_left_arm.dae</uri>
          </mesh>
        </geometry>
      </visual>
      <!-- <gravity>0</gravity> -->
    </link>
    <link name="right_arm_link">
      <inertial>
        <mass>7.0</mass>
        <inertia>
          <ixx>-0.186819 </ixx>     
          <ixy>-0.000257 </ixy>        
          <ixz>-0.000008</ixz>         
          <iyy>0.005504</iyy>       
          <iyz>-0.003203</iyz>        
          <izz>-0.183004</izz>    
        </inertia>
      </inertial>
      <collision name="right_arm_collision">
        <geometry>
          <mesh>
            <uri>model://jeff_electrician/jeff_right_arm.dae</uri>
          </mesh>
        </geometry>
      </collision>
      <visual name="right_arm_visual">
        <geometry>
          <mesh>
            <uri>model://jeff_electrician/jeff_right_arm.dae</uri>
          </mesh>
        </geometry>
      </visual>
      <!-- <gravity>0</gravity> -->
    </link>
    <joint name="left_shoulder" type="revolute">
      <pose>-0.1 -0.28 1.8 0 0 0</pose>
      <child>left_arm_link</child>
      <parent>body_link</parent>
      <axis>
        <limit>
          <lower>-3.0</lower>
          <upper>3.0</upper>
        </limit>
        <xyz>0 1 0</xyz>
        <dynamics damping="2" friction="50" />
      </axis>
    </joint>
    <joint name="right_shoulder" type="revolute">
      <pose>-0.1 0.28 1.8 0 0 0</pose>
      <child>right_arm_link</child>
      <parent>body_link</parent>
      <axis>
        <limit>
          <lower>-3.0</lower>
          <upper>3.0</upper>
        </limit>
        <xyz>0 1 0</xyz>
        <dynamics damping="2" friction="50" />
      </axis>
    </joint>
    <joint name="make_base_link_static" type="revolute">
      <parent>world</parent>
      <child>body_link</child>
      <axis>
        <limit>
          <lower>0</lower>
          <upper>0</upper>
        </limit>
        <xyz>0 0 1</xyz>
      </axis>
    </joint>
   </model>
</sdf>
